Workbook

Sheet Dashboard
A1: MISSION CONTROL: household dashboard
A2: ="Live prices · last scan: "&TEXT(INDIRECT("'Daily Log'!A5"),"ddd d mmm")&" ("&INDIRECT("'Daily Log'!B5")&")"
A4: TOTAL VALUE | C4: TAXABLE | E4: RETIREMENT | H4: CASH + T-BILLS | J4: UNREALIZED GAIN | L4: VALUE SLEEVE
A5: =SUM(Holdings!$H$5:$H$32) | C5: =SUMIF(Holdings!$B$5:$B$32,"Taxable",Holdings!$H$5:$H$32) | E5: =SUMIF(Holdings!$B$5:$B$32,"Retirement",Holdings!$H$5:$H$32) | H5: =SUMIF(Holdings!$D$5:$D$32,"Cash",Holdings!$H$5:$H$32) + SUMIF(Holdings!$D$5:$D$32,"T-bills",Holdings!$H$5:$H$32) | J5: =SUM(Holdings!$I$5:$I$32) | L5: =SUM('Value Sleeve'!$K$5:$K$14)
A6: ="household, live" | C6: =TEXT(SUMIF(Holdings!$B$5:$B$32,"Taxable",Holdings!$H$5:$H$32)/SUM(Holdings!$H$5:$H$32),"0%")&" of total" | E6: =TEXT(SUMIF(Holdings!$B$5:$B$32,"Retirement",Holdings!$H$5:$H$32)/SUM(Holdings!$H$5:$H$32),"0%")&" of total" | H6: =TEXT((SUMIF(Holdings!$D$5:$D$32,"Cash",Holdings!$H$5:$H$32) + SUMIF(Holdings!$D$5:$D$32,"T-bills",Holdings!$H$5:$H$32))/SUM(Holdings!$H$5:$H$32),"0%")&" not in stocks" | J6: ="on positions with known cost" | L6: =COUNTIF('Value Sleeve'!$G$5:$G$14,"IN ZONE")&" in buy zone"
A8: LATEST SCAN
A9: =""&INDIRECT("'Daily Log'!C5")
A10: ="▸ "&INDIRECT("'Daily Log'!D5")
A11: ="▸ Buy zones: "&INDIRECT("'Daily Log'!E5")
A12: ="▸ Rebalance/tax: "&INDIRECT("'Daily Log'!F5")
A13: ="▸ Risks: "&INDIRECT("'Daily Log'!G5")
A15: ALLOCATION vs TARGET (household) | H15: TAXABLE vs RETIREMENT | N15: chart data (don't edit)
A16: Sleeve | B16: Now $ | C16: Now % | D16: Target % | E16: Gap $ (+buy / −sell) | F16: Progress | H16: Sleeve | I16: Taxable $ | J16: Taxable % | K16: Retirement $ | L16: Retirement % | N16: Sleeve | O16: Now | P16: Target | Q16: Taxable | R16: Retirement
A17: US | B17: =SUMIF(Holdings!$D$5:$D$32,$A17,Holdings!$H$5:$H$32) | C17: =IFERROR(B17/SUM(Holdings!$H$5:$H$32),0) | D17: ='Control Center'!$B$6 | E17: =ROUND(D17*SUM(Holdings!$H$5:$H$32)-B17,-2) | F17: =SPARKLINE(C17,{"charttype","bar";"max",MAX(D17,C17,0.0001);"color1",IF(ABS(C17-D17)<='Control Center'!$B$16,"#16a34a","#f59e0b")}) | H17: US | I17: =SUMIFS(Holdings!$H$5:$H$32,Holdings!$D$5:$D$32,$H17,Holdings!$B$5:$B$32,"Taxable") | J17: =IFERROR(I17/SUMIF(Holdings!$B$5:$B$32,"Taxable",Holdings!$H$5:$H$32),0) | K17: =SUMIFS(Holdings!$H$5:$H$32,Holdings!$D$5:$D$32,$H17,Holdings!$B$5:$B$32,"Retirement") | L17: =IFERROR(K17/SUMIF(Holdings!$B$5:$B$32,"Retirement",Holdings!$H$5:$H$32),0) | N17: US | O17: =B17 | P17: =D17*SUM(Holdings!$H$5:$H$32) | Q17: =I17 | R17: =K17
A18: Intl | B18: =SUMIF(Holdings!$D$5:$D$32,$A18,Holdings!$H$5:$H$32) | C18: =IFERROR(B18/SUM(Holdings!$H$5:$H$32),0) | D18: ='Control Center'!$B$7 | E18: =ROUND(D18*SUM(Holdings!$H$5:$H$32)-B18,-2) | F18: =SPARKLINE(C18,{"charttype","bar";"max",MAX(D18,C18,0.0001);"color1",IF(ABS(C18-D18)<='Control Center'!$B$16,"#16a34a","#f59e0b")}) | H18: Intl | I18: =SUMIFS(Holdings!$H$5:$H$32,Holdings!$D$5:$D$32,$H18,Holdings!$B$5:$B$32,"Taxable") | J18: =IFERROR(I18/SUMIF(Holdings!$B$5:$B$32,"Taxable",Holdings!$H$5:$H$32),0) | K18: =SUMIFS(Holdings!$H$5:$H$32,Holdings!$D$5:$D$32,$H18,Holdings!$B$5:$B$32,"Retirement") | L18: =IFERROR(K18/SUMIF(Holdings!$B$5:$B$32,"Retirement",Holdings!$H$5:$H$32),0) | N18: Intl | O18: =B18 | P18: =D18*SUM(Holdings!$H$5:$H$32) | Q18: =I18 | R18: =K18
A19: Gold | B19: =SUMIF(Holdings!$D$5:$D$32,$A19,Holdings!$H$5:$H$32) | C19: =IFERROR(B19/SUM(Holdings!$H$5:$H$32),0) | D19: ='Control Center'!$B$8 | E19: =ROUND(D19*SUM(Holdings!$H$5:$H$32)-B19,-2) | F19: =SPARKLINE(C19,{"charttype","bar";"max",MAX(D19,C19,0.0001);"color1",IF(ABS(C19-D19)<='Control Center'!$B$16,"#16a34a","#f59e0b")}) | H19: Gold | I19: =SUMIFS(Holdings!$H$5:$H$32,Holdings!$D$5:$D$32,$H19,Holdings!$B$5:$B$32,"Taxable") | J19: =IFERROR(I19/SUMIF(Holdings!$B$5:$B$32,"Taxable",Holdings!$H$5:$H$32),0) | K19: =SUMIFS(Holdings!$H$5:$H$32,Holdings!$D$5:$D$32,$H19,Holdings!$B$5:$B$32,"Retirement") | L19: =IFERROR(K19/SUMIF(Holdings!$B$5:$B$32,"Retirement",Holdings!$H$5:$H$32),0) | N19: Gold | O19: =B19 | P19: =D19*SUM(Holdings!$H$5:$H$32) | Q19: =I19 | R19: =K19
A20: T-bills | B20: =SUMIF(Holdings!$D$5:$D$32,$A20,Holdings!$H$5:$H$32) | C20: =IFERROR(B20/SUM(Holdings!$H$5:$H$32),0) | D20: ='Control Center'!$B$9 | E20: =ROUND(D20*SUM(Holdings!$H$5:$H$32)-B20,-2) | F20: =SPARKLINE(C20,{"charttype","bar";"max",MAX(D20,C20,0.0001);"color1",IF(ABS(C20-D20)<='Control Center'!$B$16,"#16a34a","#f59e0b")}) | H20: T-bills | I20: =SUMIFS(Holdings!$H$5:$H$32,Holdings!$D$5:$D$32,$H20,Holdings!$B$5:$B$32,"Taxable") | J20: =IFERROR(I20/SUMIF(Holdings!$B$5:$B$32,"Taxable",Holdings!$H$5:$H$32),0) | K20: =SUMIFS(Holdings!$H$5:$H$32,Holdings!$D$5:$D$32,$H20,Holdings!$B$5:$B$32,"Retirement") | L20: =IFERROR(K20/SUMIF(Holdings!$B$5:$B$32,"Retirement",Holdings!$H$5:$H$32),0) | N20: T-bills | O20: =B20 | P20: =D20*SUM(Holdings!$H$5:$H$32) | Q20: =I20 | R20: =K20
A21: Satellites | B21: =SUMIF(Holdings!$D$5:$D$32,$A21,Holdings!$H$5:$H$32) | C21: =IFERROR(B21/SUM(Holdings!$H$5:$H$32),0) | D21: ='Control Center'!$B$10 | E21: =ROUND(D21*SUM(Holdings!$H$5:$H$32)-B21,-2) | F21: =SPARKLINE(C21,{"charttype","bar";"max",MAX(D21,C21,0.0001);"color1",IF(ABS(C21-D21)<='Control Center'!$B$16,"#16a34a","#f59e0b")}) | H21: Satellites | I21: =SUMIFS(Holdings!$H$5:$H$32,Holdings!$D$5:$D$32,$H21,Holdings!$B$5:$B$32,"Taxable") | J21: =IFERROR(I21/SUMIF(Holdings!$B$5:$B$32,"Taxable",Holdings!$H$5:$H$32),0) | K21: =SUMIFS(Holdings!$H$5:$H$32,Holdings!$D$5:$D$32,$H21,Holdings!$B$5:$B$32,"Retirement") | L21: =IFERROR(K21/SUMIF(Holdings!$B$5:$B$32,"Retirement",Holdings!$H$5:$H$32),0) | N21: Satellites | O21: =B21 | P21: =D21*SUM(Holdings!$H$5:$H$32) | Q21: =I21 | R21: =K21
A22: Cash | B22: =SUMIF(Holdings!$D$5:$D$32,$A22,Holdings!$H$5:$H$32) | C22: =IFERROR(B22/SUM(Holdings!$H$5:$H$32),0) | D22: ='Control Center'!$B$11 | E22: =ROUND(D22*SUM(Holdings!$H$5:$H$32)-B22,-2) | F22: =SPARKLINE(C22,{"charttype","bar";"max",MAX(D22,C22,0.0001);"color1",IF(ABS(C22-D22)<='Control Center'!$B$16,"#16a34a","#f59e0b")}) | H22: Cash | I22: =SUMIFS(Holdings!$H$5:$H$32,Holdings!$D$5:$D$32,$H22,Holdings!$B$5:$B$32,"Taxable") | J22: =IFERROR(I22/SUMIF(Holdings!$B$5:$B$32,"Taxable",Holdings!$H$5:$H$32),0) | K22: =SUMIFS(Holdings!$H$5:$H$32,Holdings!$D$5:$D$32,$H22,Holdings!$B$5:$B$32,"Retirement") | L22: =IFERROR(K22/SUMIF(Holdings!$B$5:$B$32,"Retirement",Holdings!$H$5:$H$32),0) | N22: Cash | O22: =B22 | P22: =D22*SUM(Holdings!$H$5:$H$32) | Q22: =I22 | R22: =K22
A25: ACCOUNTS | H25: WATCHLIST RIGHT NOW
A26: Account | B26: Type | C26: Value | D26: % of total | E26: Cash | F26: Gain $ | H26: In VALUE ZONE | J26: =COUNTIF(Watchlist!$K$5:$K$400,"VALUE ZONE")
A27: Brokerage | B27: Taxable | C27: =SUMIF(Holdings!$A$5:$A$32,$A27,Holdings!$H$5:$H$32) | D27: =IFERROR(C27/SUM(Holdings!$H$5:$H$32),0) | E27: =SUMIFS(Holdings!$H$5:$H$32,Holdings!$A$5:$A$32,$A27,Holdings!$D$5:$D$32,"Cash") | F27: =SUMIF(Holdings!$A$5:$A$32,$A27,Holdings!$I$5:$I$32) | H27: On WATCH | J27: =COUNTIF(Watchlist!$K$5:$K$400,"WATCH")
A28: 401(k) | B28: Retirement | C28: =SUMIF(Holdings!$A$5:$A$32,$A28,Holdings!$H$5:$H$32) | D28: =IFERROR(C28/SUM(Holdings!$H$5:$H$32),0) | E28: =SUMIFS(Holdings!$H$5:$H$32,Holdings!$A$5:$A$32,$A28,Holdings!$D$5:$D$32,"Cash") | F28: =SUMIF(Holdings!$A$5:$A$32,$A28,Holdings!$I$5:$I$32) | H28: Names tracked | J28: =COUNTA(Watchlist!$A$5:$A$400)
A29: Roth IRA | B29: Retirement | C29: =SUMIF(Holdings!$A$5:$A$32,$A29,Holdings!$H$5:$H$32) | D29: =IFERROR(C29/SUM(Holdings!$H$5:$H$32),0) | E29: =SUMIFS(Holdings!$H$5:$H$32,Holdings!$A$5:$A$32,$A29,Holdings!$D$5:$D$32,"Cash") | F29: =SUMIF(Holdings!$A$5:$A$32,$A29,Holdings!$I$5:$I$32)
A30: Twin Turbo sandbox (IBKR) | B30: Taxable | C30: =SUMIF(Holdings!$A$5:$A$32,$A30,Holdings!$H$5:$H$32) | D30: =IFERROR(C30/SUM(Holdings!$H$5:$H$32),0) | E30: =SUMIFS(Holdings!$H$5:$H$32,Holdings!$A$5:$A$32,$A30,Holdings!$D$5:$D$32,"Cash") | F30: =SUMIF(Holdings!$A$5:$A$32,$A30,Holdings!$I$5:$I$32)

Sheet Control Center
A1: CONTROL CENTER: the dials your agent works from
A2: Yellow cells are yours to change (or ask your agent to change them; it should show the impact first). Everything on the Dashboard is measured against this page.
A4: 1 · TARGET MIX (household)
A5: Sleeve | B5: Target % | C5: What's in it | D5: If you raise it…
A6: US | B6: 0.44 | C6: US stock funds + value sleeve | D6: More growth, deeper drops
A7: Intl | B7: 0.25 | C7: International stock funds | D7: More diversification away from US mega-caps
A8: Gold | B8: 0.06 | C8: Gold ETF | D8: Better crash cushion, low long-run return
A9: T-bills | B9: 0.15 | C9: 0-3 month Treasury bills | D9: Safer, lower return (~T-bill yield)
A10: Satellites | B10: 0.1 | C10: High-upside bets: bitcoin, semis, agent sandboxes | D10: More upside and much bigger swings
A11: Cash | B11: 0 | C11: Uninvested cash | D11: Cash drag
A12: Total (must be 100%) | B12: =SUM(B6:B11)
A14: 2 · RULES & DIALS
A15: Dial | B15: Current | C15: What it controls | D15: Notes
A16: Drift band (pts) | B16: 0.05 | C16: If a sleeve is this far off target, the daily note offers 2 options: sell vs fund from new money
A17: Value zone: min drop from 52w high | B17: 0.3 | C17: Watchlist/Value Sleeve flag VALUE ZONE when at least this far below the 52-week high…
A18: Value zone: max P/E | B18: 20 | C18: …AND the P/E is at or below this (ETFs flag on price only)
A19: Watch: min drop from 52w high | B19: 0.2 | C19: WATCH flag threshold
A20: Loss-harvest trigger | B20: -0.2 | C20: Value Sleeve flags HARVEST? when a name is down this much | D20: Mind the 30-day wash-sale rule across ALL accounts
A21: Harvest: min $ loss | B21: 300 | C21: tools/harvest_check.py only flags a taxable holding when the loss is at least this many dollars | D21: Small losses aren't worth 31 days out of the position
A22: Dip rule: S&P drop from high | B22: 0.05 | C22: If the S&P closes this far below its high, the next planned buy date is pulled forward | D22: One buy date per drop
A23: Satellite cap per name | B23: 5000 | C23: Max $ in any one satellite
A24: Exclusions | B24: e.g. sectors you never want | C24: Agent never recommends these
A25: Email recipients | B25: you@example.com | C25: Daily + weekly notes go only here
A28: 3 · GLOSSARY
A29: Sleeve | B29: A bucket of the portfolio with one job (US stocks, international, gold, T-bills, satellites, cash).
A30: Drift | B30: How far a sleeve has moved away from its target % because prices moved.
A31: P/E | B31: Price ÷ yearly earnings per share. Lower = cheaper (compare to the stock's own history).
A32: 52w high | B32: Highest price in the last year. 'Off high' = how far below that peak.
A33: Tax-loss harvest | B33: Selling a loser to book a loss that offsets gains you already took. No rebuy of the same thing within 30 days in any account.
A34: Satellite | B34: A small, high-upside bet outside the core.

Sheet Holdings
A1: HOLDINGS: every position in every account
A2: Yellow cells (shares, avg cost) are the only hand-entered numbers; update them from a broker screenshot. CASH / CRYPTO / sandbox rows: shares = dollar value. Prices are live.
A4: Account | B4: Type | C4: Ticker | D4: Sleeve | E4: Shares | F4: Avg cost | G4: Price | H4: Value | I4: Gain $ | J4: Gain % | K4: Note
A5: Brokerage | B5: Taxable | C5: VTI | D5: US | E5: 40 | F5: 280 | G5: =IF($C5="",,IF(OR($C5="CASH",$C5="CRYPTO",ISNUMBER(SEARCH("-",$C5))),1,IFERROR(GOOGLEFINANCE($C5,"price"),300.0))) | H5: =IF($C5="",,ROUND(N($E5)*N($G5),2)) | I5: =IF(N($F5)=0,,ROUND($H5-$E5*$F5,2)) | J5: =IF(N($F5)=0,,$G5/$F5-1) | K5: Core US
A6: Brokerage | B6: Taxable | C6: VXUS | D6: Intl | E6: 80 | F6: 60 | G6: =IF($C6="",,IF(OR($C6="CASH",$C6="CRYPTO",ISNUMBER(SEARCH("-",$C6))),1,IFERROR(GOOGLEFINANCE($C6,"price"),65.0))) | H6: =IF($C6="",,ROUND(N($E6)*N($G6),2)) | I6: =IF(N($F6)=0,,ROUND($H6-$E6*$F6,2)) | J6: =IF(N($F6)=0,,$G6/$F6-1) | K6: Core international
A7: Brokerage | B7: Taxable | C7: SGOV | D7: T-bills | E7: 50 | F7: 100 | G7: =IF($C7="",,IF(OR($C7="CASH",$C7="CRYPTO",ISNUMBER(SEARCH("-",$C7))),1,IFERROR(GOOGLEFINANCE($C7,"price"),100.0))) | H7: =IF($C7="",,ROUND(N($E7)*N($G7),2)) | I7: =IF(N($F7)=0,,ROUND($H7-$E7*$F7,2)) | J7: =IF(N($F7)=0,,$G7/$F7-1) | K7: Dry powder
A8: Brokerage | B8: Taxable | C8: AAPL | D8: US | E8: 5 | F8: 210 | G8: =IF($C8="",,IF(OR($C8="CASH",$C8="CRYPTO",ISNUMBER(SEARCH("-",$C8))),1,IFERROR(GOOGLEFINANCE($C8,"price"),230.0))) | H8: =IF($C8="",,ROUND(N($E8)*N($G8),2)) | I8: =IF(N($F8)=0,,ROUND($H8-$E8*$F8,2)) | J8: =IF(N($F8)=0,,$G8/$F8-1) | K8: Value sleeve example
A9: Brokerage | B9: Taxable | C9: CASH | D9: Cash | E9: 650 | G9: =IF($C9="",,IF(OR($C9="CASH",$C9="CRYPTO",ISNUMBER(SEARCH("-",$C9))),1,IFERROR(GOOGLEFINANCE($C9,"price"),1.0))) | H9: =IF($C9="",,ROUND(N($E9)*N($G9),2)) | I9: =IF(N($F9)=0,,ROUND($H9-$E9*$F9,2)) | J9: =IF(N($F9)=0,,$G9/$F9-1)
A10: 401(k) | B10: Retirement | C10: VTI | D10: US | E10: 30 | F10: 260 | G10: =IF($C10="",,IF(OR($C10="CASH",$C10="CRYPTO",ISNUMBER(SEARCH("-",$C10))),1,IFERROR(GOOGLEFINANCE($C10,"price"),300.0))) | H10: =IF($C10="",,ROUND(N($E10)*N($G10),2)) | I10: =IF(N($F10)=0,,ROUND($H10-$E10*$F10,2)) | J10: =IF(N($F10)=0,,$G10/$F10-1)
A11: 401(k) | B11: Retirement | C11: VXUS | D11: Intl | E11: 60 | F11: 58 | G11: =IF($C11="",,IF(OR($C11="CASH",$C11="CRYPTO",ISNUMBER(SEARCH("-",$C11))),1,IFERROR(GOOGLEFINANCE($C11,"price"),65.0))) | H11: =IF($C11="",,ROUND(N($E11)*N($G11),2)) | I11: =IF(N($F11)=0,,ROUND($H11-$E11*$F11,2)) | J11: =IF(N($F11)=0,,$G11/$F11-1)
A12: 401(k) | B12: Retirement | C12: GLDM | D12: Gold | E12: 40 | F12: 55 | G12: =IF($C12="",,IF(OR($C12="CASH",$C12="CRYPTO",ISNUMBER(SEARCH("-",$C12))),1,IFERROR(GOOGLEFINANCE($C12,"price"),62.5))) | H12: =IF($C12="",,ROUND(N($E12)*N($G12),2)) | I12: =IF(N($F12)=0,,ROUND($H12-$E12*$F12,2)) | J12: =IF(N($F12)=0,,$G12/$F12-1)
A13: 401(k) | B13: Retirement | C13: SGOV | D13: T-bills | E13: 25 | F13: 100 | G13: =IF($C13="",,IF(OR($C13="CASH",$C13="CRYPTO",ISNUMBER(SEARCH("-",$C13))),1,IFERROR(GOOGLEFINANCE($C13,"price"),100.0))) | H13: =IF($C13="",,ROUND(N($E13)*N($G13),2)) | I13: =IF(N($F13)=0,,ROUND($H13-$E13*$F13,2)) | J13: =IF(N($F13)=0,,$G13/$F13-1)
A14: 401(k) | B14: Retirement | C14: CASH | D14: Cash | E14: 100 | G14: =IF($C14="",,IF(OR($C14="CASH",$C14="CRYPTO",ISNUMBER(SEARCH("-",$C14))),1,IFERROR(GOOGLEFINANCE($C14,"price"),1.0))) | H14: =IF($C14="",,ROUND(N($E14)*N($G14),2)) | I14: =IF(N($F14)=0,,ROUND($H14-$E14*$F14,2)) | J14: =IF(N($F14)=0,,$G14/$F14-1)
A15: Roth IRA | B15: Retirement | C15: VTI | D15: US | E15: 10 | F15: 270 | G15: =IF($C15="",,IF(OR($C15="CASH",$C15="CRYPTO",ISNUMBER(SEARCH("-",$C15))),1,IFERROR(GOOGLEFINANCE($C15,"price"),300.0))) | H15: =IF($C15="",,ROUND(N($E15)*N($G15),2)) | I15: =IF(N($F15)=0,,ROUND($H15-$E15*$F15,2)) | J15: =IF(N($F15)=0,,$G15/$F15-1)
A16: Roth IRA | B16: Retirement | C16: IBIT | D16: Satellites | E16: 40 | F16: 45 | G16: =IF($C16="",,IF(OR($C16="CASH",$C16="CRYPTO",ISNUMBER(SEARCH("-",$C16))),1,IFERROR(GOOGLEFINANCE($C16,"price"),50.0))) | H16: =IF($C16="",,ROUND(N($E16)*N($G16),2)) | I16: =IF(N($F16)=0,,ROUND($H16-$E16*$F16,2)) | J16: =IF(N($F16)=0,,$G16/$F16-1) | K16: Satellite example
A17: Twin Turbo sandbox (IBKR) | B17: Taxable | C17: TWIN-TURBO | D17: Satellites | E17: 3000 | G17: =IF($C17="",,IF(OR($C17="CASH",$C17="CRYPTO",ISNUMBER(SEARCH("-",$C17))),1,IFERROR(GOOGLEFINANCE($C17,"price"),1.0))) | H17: =IF($C17="",,ROUND(N($E17)*N($G17),2)) | I17: =IF(N($F17)=0,,ROUND($H17-$E17*$F17,2)) | J17: =IF(N($F17)=0,,$G17/$F17-1) | K17: Momentum agent sandbox: value only (see Twin Turbo repo)
G18: =IF($C18="",,IF(OR($C18="CASH",$C18="CRYPTO",ISNUMBER(SEARCH("-",$C18))),1,IFERROR(GOOGLEFINANCE($C18,"price"),0))) | H18: =IF($C18="",,ROUND(N($E18)*N($G18),2)) | I18: =IF(N($F18)=0,,ROUND($H18-$E18*$F18,2)) | J18: =IF(N($F18)=0,,$G18/$F18-1)
G19: =IF($C19="",,IF(OR($C19="CASH",$C19="CRYPTO",ISNUMBER(SEARCH("-",$C19))),1,IFERROR(GOOGLEFINANCE($C19,"price"),0))) | H19: =IF($C19="",,ROUND(N($E19)*N($G19),2)) | I19: =IF(N($F19)=0,,ROUND($H19-$E19*$F19,2)) | J19: =IF(N($F19)=0,,$G19/$F19-1)
G20: =IF($C20="",,IF(OR($C20="CASH",$C20="CRYPTO",ISNUMBER(SEARCH("-",$C20))),1,IFERROR(GOOGLEFINANCE($C20,"price"),0))) | H20: =IF($C20="",,ROUND(N($E20)*N($G20),2)) | I20: =IF(N($F20)=0,,ROUND($H20-$E20*$F20,2)) | J20: =IF(N($F20)=0,,$G20/$F20-1)
G21: =IF($C21="",,IF(OR($C21="CASH",$C21="CRYPTO",ISNUMBER(SEARCH("-",$C21))),1,IFERROR(GOOGLEFINANCE($C21,"price"),0))) | H21: =IF($C21="",,ROUND(N($E21)*N($G21),2)) | I21: =IF(N($F21)=0,,ROUND($H21-$E21*$F21,2)) | J21: =IF(N($F21)=0,,$G21/$F21-1)
G22: =IF($C22="",,IF(OR($C22="CASH",$C22="CRYPTO",ISNUMBER(SEARCH("-",$C22))),1,IFERROR(GOOGLEFINANCE($C22,"price"),0))) | H22: =IF($C22="",,ROUND(N($E22)*N($G22),2)) | I22: =IF(N($F22)=0,,ROUND($H22-$E22*$F22,2)) | J22: =IF(N($F22)=0,,$G22/$F22-1)
G23: =IF($C23="",,IF(OR($C23="CASH",$C23="CRYPTO",ISNUMBER(SEARCH("-",$C23))),1,IFERROR(GOOGLEFINANCE($C23,"price"),0))) | H23: =IF($C23="",,ROUND(N($E23)*N($G23),2)) | I23: =IF(N($F23)=0,,ROUND($H23-$E23*$F23,2)) | J23: =IF(N($F23)=0,,$G23/$F23-1)
G24: =IF($C24="",,IF(OR($C24="CASH",$C24="CRYPTO",ISNUMBER(SEARCH("-",$C24))),1,IFERROR(GOOGLEFINANCE($C24,"price"),0))) | H24: =IF($C24="",,ROUND(N($E24)*N($G24),2)) | I24: =IF(N($F24)=0,,ROUND($H24-$E24*$F24,2)) | J24: =IF(N($F24)=0,,$G24/$F24-1)
G25: =IF($C25="",,IF(OR($C25="CASH",$C25="CRYPTO",ISNUMBER(SEARCH("-",$C25))),1,IFERROR(GOOGLEFINANCE($C25,"price"),0))) | H25: =IF($C25="",,ROUND(N($E25)*N($G25),2)) | I25: =IF(N($F25)=0,,ROUND($H25-$E25*$F25,2)) | J25: =IF(N($F25)=0,,$G25/$F25-1)
G26: =IF($C26="",,IF(OR($C26="CASH",$C26="CRYPTO",ISNUMBER(SEARCH("-",$C26))),1,IFERROR(GOOGLEFINANCE($C26,"price"),0))) | H26: =IF($C26="",,ROUND(N($E26)*N($G26),2)) | I26: =IF(N($F26)=0,,ROUND($H26-$E26*$F26,2)) | J26: =IF(N($F26)=0,,$G26/$F26-1)
G27: =IF($C27="",,IF(OR($C27="CASH",$C27="CRYPTO",ISNUMBER(SEARCH("-",$C27))),1,IFERROR(GOOGLEFINANCE($C27,"price"),0))) | H27: =IF($C27="",,ROUND(N($E27)*N($G27),2)) | I27: =IF(N($F27)=0,,ROUND($H27-$E27*$F27,2)) | J27: =IF(N($F27)=0,,$G27/$F27-1)
G28: =IF($C28="",,IF(OR($C28="CASH",$C28="CRYPTO",ISNUMBER(SEARCH("-",$C28))),1,IFERROR(GOOGLEFINANCE($C28,"price"),0))) | H28: =IF($C28="",,ROUND(N($E28)*N($G28),2)) | I28: =IF(N($F28)=0,,ROUND($H28-$E28*$F28,2)) | J28: =IF(N($F28)=0,,$G28/$F28-1)
G29: =IF($C29="",,IF(OR($C29="CASH",$C29="CRYPTO",ISNUMBER(SEARCH("-",$C29))),1,IFERROR(GOOGLEFINANCE($C29,"price"),0))) | H29: =IF($C29="",,ROUND(N($E29)*N($G29),2)) | I29: =IF(N($F29)=0,,ROUND($H29-$E29*$F29,2)) | J29: =IF(N($F29)=0,,$G29/$F29-1)
... G32: =IF($C32="",,IF(OR($C32="CASH",$C32="CRYPTO",ISNUMBER(SEARCH("-",$C32))),1,IFERROR(GOOGLEFINANCE($C32,"price"),0))) | H32: =IF($C32="",,ROUND(N($E32)*N($G32),2)) | I32: =IF(N($F32)=0,,ROUND($H32-$E32*$F32,2)) | J32: =IF(N($F32)=0,,$G32/$F32-1)
G34: TOTAL | H34: =SUM(H5:H32) | I34: =SUM(I5:I32)
A36: Sleeve must match a row on Control Center (US · Intl · Gold · T-bills · Satellites · Cash). Type is Taxable or Retirement.

Sheet Projection
A1: PROJECTION: where the household could be, from today's holdings
A2: Updates by itself when prices or Holdings change. Yellow cells are assumptions you can edit. Bad / Good = worst and best 5% of outcomes. Not a forecast; no new money added.
A4: Sleeve | B4: Return / yr | C4: Volatility | D4: Weight now | E4: Target weight
A5: US | B5: 0.065 | C5: 0.16 | D5: =IFERROR(SUMIF(Holdings!$D$5:$D$32,$A5,Holdings!$H$5:$H$32)/SUM(Holdings!$H$5:$H$32),0) | E5: ='Control Center'!$B$6
A6: Intl | B6: 0.074 | C6: 0.17 | D6: =IFERROR(SUMIF(Holdings!$D$5:$D$32,$A6,Holdings!$H$5:$H$32)/SUM(Holdings!$H$5:$H$32),0) | E6: ='Control Center'!$B$7
A7: Gold | B7: 0.035 | C7: 0.15 | D7: =IFERROR(SUMIF(Holdings!$D$5:$D$32,$A7,Holdings!$H$5:$H$32)/SUM(Holdings!$H$5:$H$32),0) | E7: ='Control Center'!$B$8
A8: T-bills | B8: 0.032 | C8: 0.005 | D8: =IFERROR(SUMIF(Holdings!$D$5:$D$32,$A8,Holdings!$H$5:$H$32)/SUM(Holdings!$H$5:$H$32),0) | E8: ='Control Center'!$B$9
A9: Satellites | B9: 0.08 | C9: 0.45 | D9: =IFERROR(SUMIF(Holdings!$D$5:$D$32,$A9,Holdings!$H$5:$H$32)/SUM(Holdings!$H$5:$H$32),0) | E9: ='Control Center'!$B$10
A10: Cash | B10: 0.025 | C10: 0.001 | D10: =IFERROR(SUMIF(Holdings!$D$5:$D$32,$A10,Holdings!$H$5:$H$32)/SUM(Holdings!$H$5:$H$32),0) | E10: ='Control Center'!$B$11
A12: How the sleeves move together (correlation, editable)
B13: US | C13: Intl | D13: Gold | E13: T-bills | F13: Satellites | G13: Cash
A14: US | B14: 1 | C14: 0.8 | D14: 0.15 | E14: 0 | F14: 0.5 | G14: 0
A15: Intl | B15: 0.8 | C15: 1 | D15: 0.15 | E15: 0 | F15: 0.5 | G15: 0
A16: Gold | B16: 0.15 | C16: 0.15 | D16: 1 | E16: 0 | F16: 0.15 | G16: 0
A17: T-bills | B17: 0 | C17: 0 | D17: 0 | E17: 1 | F17: 0 | G17: 0
A18: Satellites | B18: 0.5 | C18: 0.5 | D18: 0.15 | E18: 0 | F18: 1 | G18: 0
A19: Cash | B19: 0 | C19: 0 | D19: 0 | E19: 0 | F19: 0 | G19: 1
A20: Covariance (calculated)
B21: =B14*$C$5*$C$5 | C21: =C14*$C$5*$C$6 | D21: =D14*$C$5*$C$7 | E21: =E14*$C$5*$C$8 | F21: =F14*$C$5*$C$9 | G21: =G14*$C$5*$C$10 | H21: =MMULT(B21:G21,$D$5:$D$10) | I21: =MMULT(B21:G21,$E$5:$E$10)
B22: =B15*$C$6*$C$5 | C22: =C15*$C$6*$C$6 | D22: =D15*$C$6*$C$7 | E22: =E15*$C$6*$C$8 | F22: =F15*$C$6*$C$9 | G22: =G15*$C$6*$C$10 | H22: =MMULT(B22:G22,$D$5:$D$10) | I22: =MMULT(B22:G22,$E$5:$E$10)
B23: =B16*$C$7*$C$5 | C23: =C16*$C$7*$C$6 | D23: =D16*$C$7*$C$7 | E23: =E16*$C$7*$C$8 | F23: =F16*$C$7*$C$9 | G23: =G16*$C$7*$C$10 | H23: =MMULT(B23:G23,$D$5:$D$10) | I23: =MMULT(B23:G23,$E$5:$E$10)
B24: =B17*$C$8*$C$5 | C24: =C17*$C$8*$C$6 | D24: =D17*$C$8*$C$7 | E24: =E17*$C$8*$C$8 | F24: =F17*$C$8*$C$9 | G24: =G17*$C$8*$C$10 | H24: =MMULT(B24:G24,$D$5:$D$10) | I24: =MMULT(B24:G24,$E$5:$E$10)
B25: =B18*$C$9*$C$5 | C25: =C18*$C$9*$C$6 | D25: =D18*$C$9*$C$7 | E25: =E18*$C$9*$C$8 | F25: =F18*$C$9*$C$9 | G25: =G18*$C$9*$C$10 | H25: =MMULT(B25:G25,$D$5:$D$10) | I25: =MMULT(B25:G25,$E$5:$E$10)
B26: =B19*$C$10*$C$5 | C26: =C19*$C$10*$C$6 | D26: =D19*$C$10*$C$7 | E26: =E19*$C$10*$C$8 | F26: =F19*$C$10*$C$9 | G26: =G19*$C$10*$C$10 | H26: =MMULT(B26:G26,$D$5:$D$10) | I26: =MMULT(B26:G26,$E$5:$E$10)
B28: Today's mix | C28: At targets
A29: Starting value (Holdings total) | B29: =SUM(Holdings!$H$5:$H$32) | C29: =B29
A30: Expected return / yr | B30: =SUMPRODUCT($B$5:$B$10,D5:D10) | C30: =SUMPRODUCT($B$5:$B$10,E5:E10)
A31: Volatility (typical yearly swing) | B31: =SQRT(SUMPRODUCT(D5:D10,H21:H26)) | C31: =SQRT(SUMPRODUCT(E5:E10,I21:I26))
A32: Growth rate used (after volatility drag) | B32: =LN(1+B30)-B31^2/2 | C32: =LN(1+C30)-C31^2/2
A34: Years from today | B34: Bad (5%) | C34: Middle | D34: Good (95%) | E34: Middle at targets
A35: 0 | B35: =$B$29*EXP($B$32*$A35-1.645*$B$31*SQRT($A35)) | C35: =$B$29*EXP($B$32*$A35) | D35: =$B$29*EXP($B$32*$A35+1.645*$B$31*SQRT($A35)) | E35: =$C$29*EXP($C$32*$A35)
A36: 1 | B36: =$B$29*EXP($B$32*$A36-1.645*$B$31*SQRT($A36)) | C36: =$B$29*EXP($B$32*$A36) | D36: =$B$29*EXP($B$32*$A36+1.645*$B$31*SQRT($A36)) | E36: =$C$29*EXP($C$32*$A36)
A37: 2 | B37: =$B$29*EXP($B$32*$A37-1.645*$B$31*SQRT($A37)) | C37: =$B$29*EXP($B$32*$A37) | D37: =$B$29*EXP($B$32*$A37+1.645*$B$31*SQRT($A37)) | E37: =$C$29*EXP($C$32*$A37)
A38: 3 | B38: =$B$29*EXP($B$32*$A38-1.645*$B$31*SQRT($A38)) | C38: =$B$29*EXP($B$32*$A38) | D38: =$B$29*EXP($B$32*$A38+1.645*$B$31*SQRT($A38)) | E38: =$C$29*EXP($C$32*$A38)
A39: 4 | B39: =$B$29*EXP($B$32*$A39-1.645*$B$31*SQRT($A39)) | C39: =$B$29*EXP($B$32*$A39) | D39: =$B$29*EXP($B$32*$A39+1.645*$B$31*SQRT($A39)) | E39: =$C$29*EXP($C$32*$A39)
A40: 5 | B40: =$B$29*EXP($B$32*$A40-1.645*$B$31*SQRT($A40)) | C40: =$B$29*EXP($B$32*$A40) | D40: =$B$29*EXP($B$32*$A40+1.645*$B$31*SQRT($A40)) | E40: =$C$29*EXP($C$32*$A40)
A41: 6 | B41: =$B$29*EXP($B$32*$A41-1.645*$B$31*SQRT($A41)) | C41: =$B$29*EXP($B$32*$A41) | D41: =$B$29*EXP($B$32*$A41+1.645*$B$31*SQRT($A41)) | E41: =$C$29*EXP($C$32*$A41)
A42: 7 | B42: =$B$29*EXP($B$32*$A42-1.645*$B$31*SQRT($A42)) | C42: =$B$29*EXP($B$32*$A42) | D42: =$B$29*EXP($B$32*$A42+1.645*$B$31*SQRT($A42)) | E42: =$C$29*EXP($C$32*$A42)
A43: 8 | B43: =$B$29*EXP($B$32*$A43-1.645*$B$31*SQRT($A43)) | C43: =$B$29*EXP($B$32*$A43) | D43: =$B$29*EXP($B$32*$A43+1.645*$B$31*SQRT($A43)) | E43: =$C$29*EXP($C$32*$A43)
A44: 9 | B44: =$B$29*EXP($B$32*$A44-1.645*$B$31*SQRT($A44)) | C44: =$B$29*EXP($B$32*$A44) | D44: =$B$29*EXP($B$32*$A44+1.645*$B$31*SQRT($A44)) | E44: =$C$29*EXP($C$32*$A44)
...

Sheet Value Sleeve
A1: VALUE SLEEVE: beaten-down quality names you review monthly
A2: Example rows only, not recommendations. Zone = at least the Control Center drop below the 52-week high. Owned shares are pulled from Holdings automatically.
A4: Ticker | B4: Name | C4: Price | D4: 52w high | E4: Off high | F4: P/E | G4: Status | H4: Planned $ | I4: Shares | J4: Avg cost | K4: Value | L4: Gain % | M4: Why it's cheap / thesis | N4: Main risk
A5: AAPL | B5: Apple | C5: =IF($A5="",,IFERROR(GOOGLEFINANCE($A5,"price"),)) | D5: =IF($A5="",,IFERROR(GOOGLEFINANCE($A5,"high52"),)) | E5: =IF(N($D5)=0,,$C5/$D5-1) | F5: =IF($A5="",,IFERROR(GOOGLEFINANCE($A5,"pe"),)) | G5: =IF(N($C5)=0,,IF(AND(N($L5)<>0,$L5<='Control Center'!$B$20),"HARVEST?",IF($E5<=-'Control Center'!$B$17,"IN ZONE",IF($E5<=-'Control Center'!$B$19,"NEAR","ABOVE")))) | H5: 1000 | I5: =IF($A5="",,SUMIF(Holdings!$C$5:$C$32,$A5,Holdings!$E$5:$E$32)) | J5: =IFERROR(SUMPRODUCT((Holdings!$C$5:$C$32=$A5)*Holdings!$E$5:$E$32*Holdings!$F$5:$F$32)/$I5,) | K5: =IF(N($I5)=0,,ROUND($I5*$C5,2)) | L5: =IF(N($J5)=0,,$C5/$J5-1) | M5: Example row: write why the stock is cheap vs its own history | N5: Example row: what would break the thesis
A6: KO | B6: Coca-Cola | C6: =IF($A6="",,IFERROR(GOOGLEFINANCE($A6,"price"),)) | D6: =IF($A6="",,IFERROR(GOOGLEFINANCE($A6,"high52"),)) | E6: =IF(N($D6)=0,,$C6/$D6-1) | F6: =IF($A6="",,IFERROR(GOOGLEFINANCE($A6,"pe"),)) | G6: =IF(N($C6)=0,,IF(AND(N($L6)<>0,$L6<='Control Center'!$B$20),"HARVEST?",IF($E6<=-'Control Center'!$B$17,"IN ZONE",IF($E6<=-'Control Center'!$B$19,"NEAR","ABOVE")))) | H6: 1000 | I6: =IF($A6="",,SUMIF(Holdings!$C$5:$C$32,$A6,Holdings!$E$5:$E$32)) | J6: =IFERROR(SUMPRODUCT((Holdings!$C$5:$C$32=$A6)*Holdings!$E$5:$E$32*Holdings!$F$5:$F$32)/$I6,) | K6: =IF(N($I6)=0,,ROUND($I6*$C6,2)) | L6: =IF(N($J6)=0,,$C6/$J6-1) | M6: Example row | N6: Example row
A7: JNJ | B7: Johnson & Johnson | C7: =IF($A7="",,IFERROR(GOOGLEFINANCE($A7,"price"),)) | D7: =IF($A7="",,IFERROR(GOOGLEFINANCE($A7,"high52"),)) | E7: =IF(N($D7)=0,,$C7/$D7-1) | F7: =IF($A7="",,IFERROR(GOOGLEFINANCE($A7,"pe"),)) | G7: =IF(N($C7)=0,,IF(AND(N($L7)<>0,$L7<='Control Center'!$B$20),"HARVEST?",IF($E7<=-'Control Center'!$B$17,"IN ZONE",IF($E7<=-'Control Center'!$B$19,"NEAR","ABOVE")))) | H7: 1000 | I7: =IF($A7="",,SUMIF(Holdings!$C$5:$C$32,$A7,Holdings!$E$5:$E$32)) | J7: =IFERROR(SUMPRODUCT((Holdings!$C$5:$C$32=$A7)*Holdings!$E$5:$E$32*Holdings!$F$5:$F$32)/$I7,) | K7: =IF(N($I7)=0,,ROUND($I7*$C7,2)) | L7: =IF(N($J7)=0,,$C7/$J7-1) | M7: Example row | N7: Example row
A8: HD | B8: Home Depot | C8: =IF($A8="",,IFERROR(GOOGLEFINANCE($A8,"price"),)) | D8: =IF($A8="",,IFERROR(GOOGLEFINANCE($A8,"high52"),)) | E8: =IF(N($D8)=0,,$C8/$D8-1) | F8: =IF($A8="",,IFERROR(GOOGLEFINANCE($A8,"pe"),)) | G8: =IF(N($C8)=0,,IF(AND(N($L8)<>0,$L8<='Control Center'!$B$20),"HARVEST?",IF($E8<=-'Control Center'!$B$17,"IN ZONE",IF($E8<=-'Control Center'!$B$19,"NEAR","ABOVE")))) | H8: 1000 | I8: =IF($A8="",,SUMIF(Holdings!$C$5:$C$32,$A8,Holdings!$E$5:$E$32)) | J8: =IFERROR(SUMPRODUCT((Holdings!$C$5:$C$32=$A8)*Holdings!$E$5:$E$32*Holdings!$F$5:$F$32)/$I8,) | K8: =IF(N($I8)=0,,ROUND($I8*$C8,2)) | L8: =IF(N($J8)=0,,$C8/$J8-1) | M8: Example row | N8: Example row
A9: MCD | B9: McDonald's | C9: =IF($A9="",,IFERROR(GOOGLEFINANCE($A9,"price"),)) | D9: =IF($A9="",,IFERROR(GOOGLEFINANCE($A9,"high52"),)) | E9: =IF(N($D9)=0,,$C9/$D9-1) | F9: =IF($A9="",,IFERROR(GOOGLEFINANCE($A9,"pe"),)) | G9: =IF(N($C9)=0,,IF(AND(N($L9)<>0,$L9<='Control Center'!$B$20),"HARVEST?",IF($E9<=-'Control Center'!$B$17,"IN ZONE",IF($E9<=-'Control Center'!$B$19,"NEAR","ABOVE")))) | H9: 1000 | I9: =IF($A9="",,SUMIF(Holdings!$C$5:$C$32,$A9,Holdings!$E$5:$E$32)) | J9: =IFERROR(SUMPRODUCT((Holdings!$C$5:$C$32=$A9)*Holdings!$E$5:$E$32*Holdings!$F$5:$F$32)/$I9,) | K9: =IF(N($I9)=0,,ROUND($I9*$C9,2)) | L9: =IF(N($J9)=0,,$C9/$J9-1) | M9: Example row | N9: Example row
C10: =IF($A10="",,IFERROR(GOOGLEFINANCE($A10,"price"),)) | D10: =IF($A10="",,IFERROR(GOOGLEFINANCE($A10,"high52"),)) | E10: =IF(N($D10)=0,,$C10/$D10-1) | F10: =IF($A10="",,IFERROR(GOOGLEFINANCE($A10,"pe"),)) | G10: =IF(N($C10)=0,,IF(AND(N($L10)<>0,$L10<='Control Center'!$B$20),"HARVEST?",IF($E10<=-'Control Center'!$B$17,"IN ZONE",IF($E10<=-'Control Center'!$B$19,"NEAR","ABOVE")))) | I10: =IF($A10="",,SUMIF(Holdings!$C$5:$C$32,$A10,Holdings!$E$5:$E$32)) | J10: =IFERROR(SUMPRODUCT((Holdings!$C$5:$C$32=$A10)*Holdings!$E$5:$E$32*Holdings!$F$5:$F$32)/$I10,) | K10: =IF(N($I10)=0,,ROUND($I10*$C10,2)) | L10: =IF(N($J10)=0,,$C10/$J10-1)
C11: =IF($A11="",,IFERROR(GOOGLEFINANCE($A11,"price"),)) | D11: =IF($A11="",,IFERROR(GOOGLEFINANCE($A11,"high52"),)) | E11: =IF(N($D11)=0,,$C11/$D11-1) | F11: =IF($A11="",,IFERROR(GOOGLEFINANCE($A11,"pe"),)) | G11: =IF(N($C11)=0,,IF(AND(N($L11)<>0,$L11<='Control Center'!$B$20),"HARVEST?",IF($E11<=-'Control Center'!$B$17,"IN ZONE",IF($E11<=-'Control Center'!$B$19,"NEAR","ABOVE")))) | I11: =IF($A11="",,SUMIF(Holdings!$C$5:$C$32,$A11,Holdings!$E$5:$E$32)) | J11: =IFERROR(SUMPRODUCT((Holdings!$C$5:$C$32=$A11)*Holdings!$E$5:$E$32*Holdings!$F$5:$F$32)/$I11,) | K11: =IF(N($I11)=0,,ROUND($I11*$C11,2)) | L11: =IF(N($J11)=0,,$C11/$J11-1)
C12: =IF($A12="",,IFERROR(GOOGLEFINANCE($A12,"price"),)) | D12: =IF($A12="",,IFERROR(GOOGLEFINANCE($A12,"high52"),)) | E12: =IF(N($D12)=0,,$C12/$D12-1) | F12: =IF($A12="",,IFERROR(GOOGLEFINANCE($A12,"pe"),)) | G12: =IF(N($C12)=0,,IF(AND(N($L12)<>0,$L12<='Control Center'!$B$20),"HARVEST?",IF($E12<=-'Control Center'!$B$17,"IN ZONE",IF($E12<=-'Control Center'!$B$19,"NEAR","ABOVE")))) | I12: =IF($A12="",,SUMIF(Holdings!$C$5:$C$32,$A12,Holdings!$E$5:$E$32)) | J12: =IFERROR(SUMPRODUCT((Holdings!$C$5:$C$32=$A12)*Holdings!$E$5:$E$32*Holdings!$F$5:$F$32)/$I12,) | K12: =IF(N($I12)=0,,ROUND($I12*$C12,2)) | L12: =IF(N($J12)=0,,$C12/$J12-1)
C13: =IF($A13="",,IFERROR(GOOGLEFINANCE($A13,"price"),)) | D13: =IF($A13="",,IFERROR(GOOGLEFINANCE($A13,"high52"),)) | E13: =IF(N($D13)=0,,$C13/$D13-1) | F13: =IF($A13="",,IFERROR(GOOGLEFINANCE($A13,"pe"),)) | G13: =IF(N($C13)=0,,IF(AND(N($L13)<>0,$L13<='Control Center'!$B$20),"HARVEST?",IF($E13<=-'Control Center'!$B$17,"IN ZONE",IF($E13<=-'Control Center'!$B$19,"NEAR","ABOVE")))) | I13: =IF($A13="",,SUMIF(Holdings!$C$5:$C$32,$A13,Holdings!$E$5:$E$32)) | J13: =IFERROR(SUMPRODUCT((Holdings!$C$5:$C$32=$A13)*Holdings!$E$5:$E$32*Holdings!$F$5:$F$32)/$I13,) | K13: =IF(N($I13)=0,,ROUND($I13*$C13,2)) | L13: =IF(N($J13)=0,,$C13/$J13-1)
C14: =IF($A14="",,IFERROR(GOOGLEFINANCE($A14,"price"),)) | D14: =IF($A14="",,IFERROR(GOOGLEFINANCE($A14,"high52"),)) | E14: =IF(N($D14)=0,,$C14/$D14-1) | F14: =IF($A14="",,IFERROR(GOOGLEFINANCE($A14,"pe"),)) | G14: =IF(N($C14)=0,,IF(AND(N($L14)<>0,$L14<='Control Center'!$B$20),"HARVEST?",IF($E14<=-'Control Center'!$B$17,"IN ZONE",IF($E14<=-'Control Center'!$B$19,"NEAR","ABOVE")))) | I14: =IF($A14="",,SUMIF(Holdings!$C$5:$C$32,$A14,Holdings!$E$5:$E$32)) | J14: =IFERROR(SUMPRODUCT((Holdings!$C$5:$C$32=$A14)*Holdings!$E$5:$E$32*Holdings!$F$5:$F$32)/$I14,) | K14: =IF(N($I14)=0,,ROUND($I14*$C14,2)) | L14: =IF(N($J14)=0,,$C14/$J14-1)
G15: TOTAL | H15: =SUM(H5:H14) | K15: =SUM(K5:K14)

Sheet Watchlist
A1: WATCHLIST: names you don't need to own, scanned for value
A2: Live prices. VALUE ZONE / WATCH thresholds come from Control Center. Add or remove tickers freely (column A); copy a row's formulas down for new rows.
A4: Ticker | B4: Name | C4: Group | D4: Price | E4: 52w low | F4: 52w high | G4: Off high | H4: Range pos. | I4: P/E | J4: Mkt cap $B | K4: Flag | L4: Agent note
A5: NVDA | B5: =IFERROR(GOOGLEFINANCE($A5,"name"),) | C5: Semis & hardware | D5: =IFERROR(GOOGLEFINANCE($A5,"price"),) | E5: =IFERROR(GOOGLEFINANCE($A5,"low52"),) | F5: =IFERROR(GOOGLEFINANCE($A5,"high52"),) | G5: =IF(N($F5)=0,,$D5/$F5-1) | H5: =IF(N($F5)-N($E5)<=0,,($D5-$E5)/($F5-$E5)) | I5: =IFERROR(GOOGLEFINANCE($A5,"pe"),) | J5: =IFERROR(GOOGLEFINANCE($A5,"marketcap")/1E9,) | K5: =IF(N($D5)=0,,IF(AND($G5<=-'Control Center'!$B$17,AND(N($I5)>0,$I5<='Control Center'!$B$18)),"VALUE ZONE",IF($G5<=-'Control Center'!$B$19,"WATCH","—")))
A6: AVGO | B6: =IFERROR(GOOGLEFINANCE($A6,"name"),) | C6: Semis & hardware | D6: =IFERROR(GOOGLEFINANCE($A6,"price"),) | E6: =IFERROR(GOOGLEFINANCE($A6,"low52"),) | F6: =IFERROR(GOOGLEFINANCE($A6,"high52"),) | G6: =IF(N($F6)=0,,$D6/$F6-1) | H6: =IF(N($F6)-N($E6)<=0,,($D6-$E6)/($F6-$E6)) | I6: =IFERROR(GOOGLEFINANCE($A6,"pe"),) | J6: =IFERROR(GOOGLEFINANCE($A6,"marketcap")/1E9,) | K6: =IF(N($D6)=0,,IF(AND($G6<=-'Control Center'!$B$17,AND(N($I6)>0,$I6<='Control Center'!$B$18)),"VALUE ZONE",IF($G6<=-'Control Center'!$B$19,"WATCH","—")))
A7: AMD | B7: =IFERROR(GOOGLEFINANCE($A7,"name"),) | C7: Semis & hardware | D7: =IFERROR(GOOGLEFINANCE($A7,"price"),) | E7: =IFERROR(GOOGLEFINANCE($A7,"low52"),) | F7: =IFERROR(GOOGLEFINANCE($A7,"high52"),) | G7: =IF(N($F7)=0,,$D7/$F7-1) | H7: =IF(N($F7)-N($E7)<=0,,($D7-$E7)/($F7-$E7)) | I7: =IFERROR(GOOGLEFINANCE($A7,"pe"),) | J7: =IFERROR(GOOGLEFINANCE($A7,"marketcap")/1E9,) | K7: =IF(N($D7)=0,,IF(AND($G7<=-'Control Center'!$B$17,AND(N($I7)>0,$I7<='Control Center'!$B$18)),"VALUE ZONE",IF($G7<=-'Control Center'!$B$19,"WATCH","—")))
A8: MU | B8: =IFERROR(GOOGLEFINANCE($A8,"name"),) | C8: Semis & hardware | D8: =IFERROR(GOOGLEFINANCE($A8,"price"),) | E8: =IFERROR(GOOGLEFINANCE($A8,"low52"),) | F8: =IFERROR(GOOGLEFINANCE($A8,"high52"),) | G8: =IF(N($F8)=0,,$D8/$F8-1) | H8: =IF(N($F8)-N($E8)<=0,,($D8-$E8)/($F8-$E8)) | I8: =IFERROR(GOOGLEFINANCE($A8,"pe"),) | J8: =IFERROR(GOOGLEFINANCE($A8,"marketcap")/1E9,) | K8: =IF(N($D8)=0,,IF(AND($G8<=-'Control Center'!$B$17,AND(N($I8)>0,$I8<='Control Center'!$B$18)),"VALUE ZONE",IF($G8<=-'Control Center'!$B$19,"WATCH","—")))
A9: TSM | B9: =IFERROR(GOOGLEFINANCE($A9,"name"),) | C9: Semis & hardware | D9: =IFERROR(GOOGLEFINANCE($A9,"price"),) | E9: =IFERROR(GOOGLEFINANCE($A9,"low52"),) | F9: =IFERROR(GOOGLEFINANCE($A9,"high52"),) | G9: =IF(N($F9)=0,,$D9/$F9-1) | H9: =IF(N($F9)-N($E9)<=0,,($D9-$E9)/($F9-$E9)) | I9: =IFERROR(GOOGLEFINANCE($A9,"pe"),) | J9: =IFERROR(GOOGLEFINANCE($A9,"marketcap")/1E9,) | K9: =IF(N($D9)=0,,IF(AND($G9<=-'Control Center'!$B$17,AND(N($I9)>0,$I9<='Control Center'!$B$18)),"VALUE ZONE",IF($G9<=-'Control Center'!$B$19,"WATCH","—")))
A10: ASML | B10: =IFERROR(GOOGLEFINANCE($A10,"name"),) | C10: Semis & hardware | D10: =IFERROR(GOOGLEFINANCE($A10,"price"),) | E10: =IFERROR(GOOGLEFINANCE($A10,"low52"),) | F10: =IFERROR(GOOGLEFINANCE($A10,"high52"),) | G10: =IF(N($F10)=0,,$D10/$F10-1) | H10: =IF(N($F10)-N($E10)<=0,,($D10-$E10)/($F10-$E10)) | I10: =IFERROR(GOOGLEFINANCE($A10,"pe"),) | J10: =IFERROR(GOOGLEFINANCE($A10,"marketcap")/1E9,) | K10: =IF(N($D10)=0,,IF(AND($G10<=-'Control Center'!$B$17,AND(N($I10)>0,$I10<='Control Center'!$B$18)),"VALUE ZONE",IF($G10<=-'Control Center'!$B$19,"WATCH","—")))
A11: AMAT | B11: =IFERROR(GOOGLEFINANCE($A11,"name"),) | C11: Semis & hardware | D11: =IFERROR(GOOGLEFINANCE($A11,"price"),) | E11: =IFERROR(GOOGLEFINANCE($A11,"low52"),) | F11: =IFERROR(GOOGLEFINANCE($A11,"high52"),) | G11: =IF(N($F11)=0,,$D11/$F11-1) | H11: =IF(N($F11)-N($E11)<=0,,($D11-$E11)/($F11-$E11)) | I11: =IFERROR(GOOGLEFINANCE($A11,"pe"),) | J11: =IFERROR(GOOGLEFINANCE($A11,"marketcap")/1E9,) | K11: =IF(N($D11)=0,,IF(AND($G11<=-'Control Center'!$B$17,AND(N($I11)>0,$I11<='Control Center'!$B$18)),"VALUE ZONE",IF($G11<=-'Control Center'!$B$19,"WATCH","—")))
A12: LRCX | B12: =IFERROR(GOOGLEFINANCE($A12,"name"),) | C12: Semis & hardware | D12: =IFERROR(GOOGLEFINANCE($A12,"price"),) | E12: =IFERROR(GOOGLEFINANCE($A12,"low52"),) | F12: =IFERROR(GOOGLEFINANCE($A12,"high52"),) | G12: =IF(N($F12)=0,,$D12/$F12-1) | H12: =IF(N($F12)-N($E12)<=0,,($D12-$E12)/($F12-$E12)) | I12: =IFERROR(GOOGLEFINANCE($A12,"pe"),) | J12: =IFERROR(GOOGLEFINANCE($A12,"marketcap")/1E9,) | K12: =IF(N($D12)=0,,IF(AND($G12<=-'Control Center'!$B$17,AND(N($I12)>0,$I12<='Control Center'!$B$18)),"VALUE ZONE",IF($G12<=-'Control Center'!$B$19,"WATCH","—")))
A13: KLAC | B13: =IFERROR(GOOGLEFINANCE($A13,"name"),) | C13: Semis & hardware | D13: =IFERROR(GOOGLEFINANCE($A13,"price"),) | E13: =IFERROR(GOOGLEFINANCE($A13,"low52"),) | F13: =IFERROR(GOOGLEFINANCE($A13,"high52"),) | G13: =IF(N($F13)=0,,$D13/$F13-1) | H13: =IF(N($F13)-N($E13)<=0,,($D13-$E13)/($F13-$E13)) | I13: =IFERROR(GOOGLEFINANCE($A13,"pe"),) | J13: =IFERROR(GOOGLEFINANCE($A13,"marketcap")/1E9,) | K13: =IF(N($D13)=0,,IF(AND($G13<=-'Control Center'!$B$17,AND(N($I13)>0,$I13<='Control Center'!$B$18)),"VALUE ZONE",IF($G13<=-'Control Center'!$B$19,"WATCH","—")))
A14: QCOM | B14: =IFERROR(GOOGLEFINANCE($A14,"name"),) | C14: Semis & hardware | D14: =IFERROR(GOOGLEFINANCE($A14,"price"),) | E14: =IFERROR(GOOGLEFINANCE($A14,"low52"),) | F14: =IFERROR(GOOGLEFINANCE($A14,"high52"),) | G14: =IF(N($F14)=0,,$D14/$F14-1) | H14: =IF(N($F14)-N($E14)<=0,,($D14-$E14)/($F14-$E14)) | I14: =IFERROR(GOOGLEFINANCE($A14,"pe"),) | J14: =IFERROR(GOOGLEFINANCE($A14,"marketcap")/1E9,) | K14: =IF(N($D14)=0,,IF(AND($G14<=-'Control Center'!$B$17,AND(N($I14)>0,$I14<='Control Center'!$B$18)),"VALUE ZONE",IF($G14<=-'Control Center'!$B$19,"WATCH","—")))
A15: TXN | B15: =IFERROR(GOOGLEFINANCE($A15,"name"),) | C15: Semis & hardware | D15: =IFERROR(GOOGLEFINANCE($A15,"price"),) | E15: =IFERROR(GOOGLEFINANCE($A15,"low52"),) | F15: =IFERROR(GOOGLEFINANCE($A15,"high52"),) | G15: =IF(N($F15)=0,,$D15/$F15-1) | H15: =IF(N($F15)-N($E15)<=0,,($D15-$E15)/($F15-$E15)) | I15: =IFERROR(GOOGLEFINANCE($A15,"pe"),) | J15: =IFERROR(GOOGLEFINANCE($A15,"marketcap")/1E9,) | K15: =IF(N($D15)=0,,IF(AND($G15<=-'Control Center'!$B$17,AND(N($I15)>0,$I15<='Control Center'!$B$18)),"VALUE ZONE",IF($G15<=-'Control Center'!$B$19,"WATCH","—")))
A16: INTC | B16: =IFERROR(GOOGLEFINANCE($A16,"name"),) | C16: Semis & hardware | D16: =IFERROR(GOOGLEFINANCE($A16,"price"),) | E16: =IFERROR(GOOGLEFINANCE($A16,"low52"),) | F16: =IFERROR(GOOGLEFINANCE($A16,"high52"),) | G16: =IF(N($F16)=0,,$D16/$F16-1) | H16: =IF(N($F16)-N($E16)<=0,,($D16-$E16)/($F16-$E16)) | I16: =IFERROR(GOOGLEFINANCE($A16,"pe"),) | J16: =IFERROR(GOOGLEFINANCE($A16,"marketcap")/1E9,) | K16: =IF(N($D16)=0,,IF(AND($G16<=-'Control Center'!$B$17,AND(N($I16)>0,$I16<='Control Center'!$B$18)),"VALUE ZONE",IF($G16<=-'Control Center'!$B$19,"WATCH","—")))
... A125: CME | B125: =IFERROR(GOOGLEFINANCE($A125,"name"),) | C125: Payments & exchanges | D125: =IFERROR(GOOGLEFINANCE($A125,"price"),) | E125: =IFERROR(GOOGLEFINANCE($A125,"low52"),) | F125: =IFERROR(GOOGLEFINANCE($A125,"high52"),) | G125: =IF(N($F125)=0,,$D125/$F125-1) | H125: =IF(N($F125)-N($E125)<=0,,($D125-$E125)/($F125-$E125)) | I125: =IFERROR(GOOGLEFINANCE($A125,"pe"),) | J125: =IFERROR(GOOGLEFINANCE($A125,"marketcap")/1E9,) | K125: =IF(N($D125)=0,,IF(AND($G125<=-'Control Center'!$B$17,AND(N($I125)>0,$I125<='Control Center'!$B$18)),"VALUE ZONE",IF($G125<=-'Control Center'!$B$19,"WATCH","—")))
A126: SPY | B126: =IFERROR(GOOGLEFINANCE($A126,"name"),) | C126: ETFs | D126: =IFERROR(GOOGLEFINANCE($A126,"price"),) | E126: =IFERROR(GOOGLEFINANCE($A126,"low52"),) | F126: =IFERROR(GOOGLEFINANCE($A126,"high52"),) | G126: =IF(N($F126)=0,,$D126/$F126-1) | H126: =IF(N($F126)-N($E126)<=0,,($D126-$E126)/($F126-$E126)) | I126: =IFERROR(GOOGLEFINANCE($A126,"pe"),) | J126: =IFERROR(GOOGLEFINANCE($A126,"marketcap")/1E9,) | K126: =IF(N($D126)=0,,IF(AND($G126<=-'Control Center'!$B$17,TRUE),"VALUE ZONE",IF($G126<=-'Control Center'!$B$19,"WATCH","—")))
A127: QQQ | B127: =IFERROR(GOOGLEFINANCE($A127,"name"),) | C127: ETFs | D127: =IFERROR(GOOGLEFINANCE($A127,"price"),) | E127: =IFERROR(GOOGLEFINANCE($A127,"low52"),) | F127: =IFERROR(GOOGLEFINANCE($A127,"high52"),) | G127: =IF(N($F127)=0,,$D127/$F127-1) | H127: =IF(N($F127)-N($E127)<=0,,($D127-$E127)/($F127-$E127)) | I127: =IFERROR(GOOGLEFINANCE($A127,"pe"),) | J127: =IFERROR(GOOGLEFINANCE($A127,"marketcap")/1E9,) | K127: =IF(N($D127)=0,,IF(AND($G127<=-'Control Center'!$B$17,TRUE),"VALUE ZONE",IF($G127<=-'Control Center'!$B$19,"WATCH","—")))
A128: VTI | B128: =IFERROR(GOOGLEFINANCE($A128,"name"),) | C128: ETFs | D128: =IFERROR(GOOGLEFINANCE($A128,"price"),) | E128: =IFERROR(GOOGLEFINANCE($A128,"low52"),) | F128: =IFERROR(GOOGLEFINANCE($A128,"high52"),) | G128: =IF(N($F128)=0,,$D128/$F128-1) | H128: =IF(N($F128)-N($E128)<=0,,($D128-$E128)/($F128-$E128)) | I128: =IFERROR(GOOGLEFINANCE($A128,"pe"),) | J128: =IFERROR(GOOGLEFINANCE($A128,"marketcap")/1E9,) | K128: =IF(N($D128)=0,,IF(AND($G128<=-'Control Center'!$B$17,TRUE),"VALUE ZONE",IF($G128<=-'Control Center'!$B$19,"WATCH","—")))
A129: VXUS | B129: =IFERROR(GOOGLEFINANCE($A129,"name"),) | C129: ETFs | D129: =IFERROR(GOOGLEFINANCE($A129,"price"),) | E129: =IFERROR(GOOGLEFINANCE($A129,"low52"),) | F129: =IFERROR(GOOGLEFINANCE($A129,"high52"),) | G129: =IF(N($F129)=0,,$D129/$F129-1) | H129: =IF(N($F129)-N($E129)<=0,,($D129-$E129)/($F129-$E129)) | I129: =IFERROR(GOOGLEFINANCE($A129,"pe"),) | J129: =IFERROR(GOOGLEFINANCE($A129,"marketcap")/1E9,) | K129: =IF(N($D129)=0,,IF(AND($G129<=-'Control Center'!$B$17,TRUE),"VALUE ZONE",IF($G129<=-'Control Center'!$B$19,"WATCH","—")))
A130: SMH | B130: =IFERROR(GOOGLEFINANCE($A130,"name"),) | C130: ETFs | D130: =IFERROR(GOOGLEFINANCE($A130,"price"),) | E130: =IFERROR(GOOGLEFINANCE($A130,"low52"),) | F130: =IFERROR(GOOGLEFINANCE($A130,"high52"),) | G130: =IF(N($F130)=0,,$D130/$F130-1) | H130: =IF(N($F130)-N($E130)<=0,,($D130-$E130)/($F130-$E130)) | I130: =IFERROR(GOOGLEFINANCE($A130,"pe"),) | J130: =IFERROR(GOOGLEFINANCE($A130,"marketcap")/1E9,) | K130: =IF(N($D130)=0,,IF(AND($G130<=-'Control Center'!$B$17,TRUE),"VALUE ZONE",IF($G130<=-'Control Center'!$B$19,"WATCH","—")))
A131: XLV | B131: =IFERROR(GOOGLEFINANCE($A131,"name"),) | C131: ETFs | D131: =IFERROR(GOOGLEFINANCE($A131,"price"),) | E131: =IFERROR(GOOGLEFINANCE($A131,"low52"),) | F131: =IFERROR(GOOGLEFINANCE($A131,"high52"),) | G131: =IF(N($F131)=0,,$D131/$F131-1) | H131: =IF(N($F131)-N($E131)<=0,,($D131-$E131)/($F131-$E131)) | I131: =IFERROR(GOOGLEFINANCE($A131,"pe"),) | J131: =IFERROR(GOOGLEFINANCE($A131,"marketcap")/1E9,) | K131: =IF(N($D131)=0,,IF(AND($G131<=-'Control Center'!$B$17,TRUE),"VALUE ZONE",IF($G131<=-'Control Center'!$B$19,"WATCH","—")))
A132: XLE | B132: =IFERROR(GOOGLEFINANCE($A132,"name"),) | C132: ETFs | D132: =IFERROR(GOOGLEFINANCE($A132,"price"),) | E132: =IFERROR(GOOGLEFINANCE($A132,"low52"),) | F132: =IFERROR(GOOGLEFINANCE($A132,"high52"),) | G132: =IF(N($F132)=0,,$D132/$F132-1) | H132: =IF(N($F132)-N($E132)<=0,,($D132-$E132)/($F132-$E132)) | I132: =IFERROR(GOOGLEFINANCE($A132,"pe"),) | J132: =IFERROR(GOOGLEFINANCE($A132,"marketcap")/1E9,) | K132: =IF(N($D132)=0,,IF(AND($G132<=-'Control Center'!$B$17,TRUE),"VALUE ZONE",IF($G132<=-'Control Center'!$B$19,"WATCH","—")))
A133: XLU | B133: =IFERROR(GOOGLEFINANCE($A133,"name"),) | C133: ETFs | D133: =IFERROR(GOOGLEFINANCE($A133,"price"),) | E133: =IFERROR(GOOGLEFINANCE($A133,"low52"),) | F133: =IFERROR(GOOGLEFINANCE($A133,"high52"),) | G133: =IF(N($F133)=0,,$D133/$F133-1) | H133: =IF(N($F133)-N($E133)<=0,,($D133-$E133)/($F133-$E133)) | I133: =IFERROR(GOOGLEFINANCE($A133,"pe"),) | J133: =IFERROR(GOOGLEFINANCE($A133,"marketcap")/1E9,) | K133: =IF(N($D133)=0,,IF(AND($G133<=-'Control Center'!$B$17,TRUE),"VALUE ZONE",IF($G133<=-'Control Center'!$B$19,"WATCH","—")))
A134: IJR | B134: =IFERROR(GOOGLEFINANCE($A134,"name"),) | C134: ETFs | D134: =IFERROR(GOOGLEFINANCE($A134,"price"),) | E134: =IFERROR(GOOGLEFINANCE($A134,"low52"),) | F134: =IFERROR(GOOGLEFINANCE($A134,"high52"),) | G134: =IF(N($F134)=0,,$D134/$F134-1) | H134: =IF(N($F134)-N($E134)<=0,,($D134-$E134)/($F134-$E134)) | I134: =IFERROR(GOOGLEFINANCE($A134,"pe"),) | J134: =IFERROR(GOOGLEFINANCE($A134,"marketcap")/1E9,) | K134: =IF(N($D134)=0,,IF(AND($G134<=-'Control Center'!$B$17,TRUE),"VALUE ZONE",IF($G134<=-'Control Center'!$B$19,"WATCH","—")))
A135: GLDM | B135: =IFERROR(GOOGLEFINANCE($A135,"name"),) | C135: ETFs | D135: =IFERROR(GOOGLEFINANCE($A135,"price"),) | E135: =IFERROR(GOOGLEFINANCE($A135,"low52"),) | F135: =IFERROR(GOOGLEFINANCE($A135,"high52"),) | G135: =IF(N($F135)=0,,$D135/$F135-1) | H135: =IF(N($F135)-N($E135)<=0,,($D135-$E135)/($F135-$E135)) | I135: =IFERROR(GOOGLEFINANCE($A135,"pe"),) | J135: =IFERROR(GOOGLEFINANCE($A135,"marketcap")/1E9,) | K135: =IF(N($D135)=0,,IF(AND($G135<=-'Control Center'!$B$17,TRUE),"VALUE ZONE",IF($G135<=-'Control Center'!$B$19,"WATCH","—")))
A136: SGOV | B136: =IFERROR(GOOGLEFINANCE($A136,"name"),) | C136: ETFs | D136: =IFERROR(GOOGLEFINANCE($A136,"price"),) | E136: =IFERROR(GOOGLEFINANCE($A136,"low52"),) | F136: =IFERROR(GOOGLEFINANCE($A136,"high52"),) | G136: =IF(N($F136)=0,,$D136/$F136-1) | H136: =IF(N($F136)-N($E136)<=0,,($D136-$E136)/($F136-$E136)) | I136: =IFERROR(GOOGLEFINANCE($A136,"pe"),) | J136: =IFERROR(GOOGLEFINANCE($A136,"marketcap")/1E9,) | K136: =IF(N($D136)=0,,IF(AND($G136<=-'Control Center'!$B$17,TRUE),"VALUE ZONE",IF($G136<=-'Control Center'!$B$19,"WATCH","—")))
A137: SCHD | B137: =IFERROR(GOOGLEFINANCE($A137,"name"),) | C137: ETFs | D137: =IFERROR(GOOGLEFINANCE($A137,"price"),) | E137: =IFERROR(GOOGLEFINANCE($A137,"low52"),) | F137: =IFERROR(GOOGLEFINANCE($A137,"high52"),) | G137: =IF(N($F137)=0,,$D137/$F137-1) | H137: =IF(N($F137)-N($E137)<=0,,($D137-$E137)/($F137-$E137)) | I137: =IFERROR(GOOGLEFINANCE($A137,"pe"),) | J137: =IFERROR(GOOGLEFINANCE($A137,"marketcap")/1E9,) | K137: =IF(N($D137)=0,,IF(AND($G137<=-'Control Center'!$B$17,TRUE),"VALUE ZONE",IF($G137<=-'Control Center'!$B$19,"WATCH","—")))
... A141: EWJ | B141: =IFERROR(GOOGLEFINANCE($A141,"name"),) | C141: ETFs | D141: =IFERROR(GOOGLEFINANCE($A141,"price"),) | E141: =IFERROR(GOOGLEFINANCE($A141,"low52"),) | F141: =IFERROR(GOOGLEFINANCE($A141,"high52"),) | G141: =IF(N($F141)=0,,$D141/$F141-1) | H141: =IF(N($F141)-N($E141)<=0,,($D141-$E141)/($F141-$E141)) | I141: =IFERROR(GOOGLEFINANCE($A141,"pe"),) | J141: =IFERROR(GOOGLEFINANCE($A141,"marketcap")/1E9,) | K141: =IF(N($D141)=0,,IF(AND($G141<=-'Control Center'!$B$17,TRUE),"VALUE ZONE",IF($G141<=-'Control Center'!$B$19,"WATCH","—")))

Sheet Daily Log
A1: DAILY LOG: every scan leaves a note here (newest on top)
A2: Written by your agent's scans (prompts/daily-scan.md). Research only: you decide every trade.
A4: Date | B4: Scan | C4: Headline | D4: Ideas (buy / hold / trim) | E4: Buy-zone alerts | F4: Rebalance & tax | G4: Risks
A5: 46309 | B5: Setup | C5: Demo tracker created. Replace demo holdings with yours, then run the first scan. | D5: None yet. | E5: See Value Sleeve and Watchlist flags. | F5: Compare Dashboard gaps with the drift band. | G5: None logged.

Sheet History
A1: HISTORY: one row per after-close scan (feeds the timeline chart)
A3: Date | B3: Total | C3: Benchmark | D3: You (index) | E3: Benchmark (index) | F3: Note
A4: 46024 | B4: 46145 | C4: 100 | D4: =IF($B4="",NA(),$B4/$B$4*100) | E4: =IF($C4="",NA(),$C4/$C$4*100) | F4: Demo start
A5: 46055 | B5: 46698 | C5: 101.2 | D5: =IF($B5="",NA(),$B5/$B$4*100) | E5: =IF($C5="",NA(),$C5/$C$4*100) | F5: Demo
A6: 46083 | B6: 45960 | C6: 99.1 | D6: =IF($B6="",NA(),$B6/$B$4*100) | E6: =IF($C6="",NA(),$C6/$C$4*100) | F6: Demo
A7: 46113 | B7: 47252 | C7: 102.6 | D7: =IF($B7="",NA(),$B7/$B$4*100) | E7: =IF($C7="",NA(),$C7/$C$4*100) | F7: Demo
A8: 46143 | B8: 47898 | C8: 103.9 | D8: =IF($B8="",NA(),$B8/$B$4*100) | E8: =IF($C8="",NA(),$C8/$C$4*100) | F8: Demo
A9: 46174 | B9: 48314 | C9: 105 | D9: =IF($B9="",NA(),$B9/$B$4*100) | E9: =IF($C9="",NA(),$C9/$C$4*100) | F9: Demo
A10: 46204 | B10: 48913 | C10: 106.8 | D10: =IF($B10="",NA(),$B10/$B$4*100) | E10: =IF($C10="",NA(),$C10/$C$4*100) | F10: Demo
A11: 46237 | B11: 48637 | C11: 105.9 | D11: =IF($B11="",NA(),$B11/$B$4*100) | E11: =IF($C11="",NA(),$C11/$C$4*100) | F11: Demo
A12: 46266 | B12: 49467 | C12: 107.7 | D12: =IF($B12="",NA(),$B12/$B$4*100) | E12: =IF($C12="",NA(),$C12/$C$4*100) | F12: Demo
A13: 46296 | B13: 50000 | C13: 108.9 | D13: =IF($B13="",NA(),$B13/$B$4*100) | E13: =IF($C13="",NA(),$C13/$C$4*100) | F13: Demo
D14: =IF($B14="",NA(),$B14/$B$4*100) | E14: =IF($C14="",NA(),$C14/$C$4*100)
D15: =IF($B15="",NA(),$B15/$B$4*100) | E15: =IF($C15="",NA(),$C15/$C$4*100)
D16: =IF($B16="",NA(),$B16/$B$4*100) | E16: =IF($C16="",NA(),$C16/$C$4*100)
D17: =IF($B17="",NA(),$B17/$B$4*100) | E17: =IF($C17="",NA(),$C17/$C$4*100)
D18: =IF($B18="",NA(),$B18/$B$4*100) | E18: =IF($C18="",NA(),$C18/$C$4*100)
D19: =IF($B19="",NA(),$B19/$B$4*100) | E19: =IF($C19="",NA(),$C19/$C$4*100)
D20: =IF($B20="",NA(),$B20/$B$4*100) | E20: =IF($C20="",NA(),$C20/$C$4*100)
D21: =IF($B21="",NA(),$B21/$B$4*100) | E21: =IF($C21="",NA(),$C21/$C$4*100)
D22: =IF($B22="",NA(),$B22/$B$4*100) | E22: =IF($C22="",NA(),$C22/$C$4*100)
D23: =IF($B23="",NA(),$B23/$B$4*100) | E23: =IF($C23="",NA(),$C23/$C$4*100)
D24: =IF($B24="",NA(),$B24/$B$4*100) | E24: =IF($C24="",NA(),$C24/$C$4*100)
D25: =IF($B25="",NA(),$B25/$B$4*100) | E25: =IF($C25="",NA(),$C25/$C$4*100)
... D399: =IF($B399="",NA(),$B399/$B$4*100) | E399: =IF($C399="",NA(),$C399/$C$4*100)
